<?xml version="1.0" ?>
<!-- =================================================================================== -->
<!-- |    This document was autogenerated by xacro from robot.urdf                     | -->
<!-- |    EDITING THIS FILE BY HAND IS NOT RECOMMENDED                                 | -->
<!-- =================================================================================== -->
<robot name="sam_bot">
  <!-- Robot Base -->
  <link name="base_link">
    <visual>
      <geometry>
        <box size="0.2 0.2 0.01"/>
      </geometry>
      <material name="Cyan">
        <color rgba="0 1.0 1.0 1.0"/>
      </material>
    </visual>
    <visual>
      <origin rpy="0 0 0" xyz="0.0 0.0 0.11"/>
      <geometry>
        <cylinder length="0.2" radius="0.07"/>
      </geometry>
      <material name="blue"/>
    </visual>
    <visual>
      <origin rpy="0 0 0" xyz="0.11 0.0 0.11"/>
      <geometry>
        <cylinder length="0.1" radius="0.01"/>
      </geometry>
      <material name="blue"/>
    </visual>
    <visual>
      <origin rpy="0 1 0" xyz="0.08 0.0 0.060000000000000005"/>
      <geometry>
        <cylinder length="0.07" radius="0.01"/>
      </geometry>
      <material name="blue"/>
    </visual>
    <visual>
      <origin rpy="0 -1.5 0" xyz="0.08 0.0 0.16"/>
      <geometry>
        <cylinder length="0.07" radius="0.01"/>
      </geometry>
      <material name="blue"/>
    </visual>
    <collision>
      <geometry>
        <box size="0.2 0.2 0.01"/>
      </geometry>
    </collision>
    <collision>
      <origin rpy="0 0 0" xyz="0.025 0.0 0.11"/>
      <geometry>
        <box size="0.2 0.14 0.2"/>
      </geometry>
    </collision>
    <inertial>
      <origin rpy="1.5707963267948966 0 1.5707963267948966" xyz="0 0 0"/>
      <mass value="15"/>
      <inertia ixx="0.05012500000000002" ixy="0.0" ixz="0.0" iyy="0.10000000000000002" iyz="0.0" izz="0.05012500000000002"/>
    </inertial>
  </link>
  <!-- Robot Footprint -->
  <link name="base_footprint"/>
  <joint name="base_joint" type="fixed">
    <parent link="base_link"/>
    <child link="base_footprint"/>
    <origin rpy="0 0 0" xyz="0.0 0.0 -0.15000000000000002"/>
  </joint>
  <link name="drivewhl_l_link">
    <visual>
      <origin rpy="1.5707963267948966 0 0" xyz="0 0 0"/>
      <geometry>
        <cylinder length="0.04" radius="0.1"/>
      </geometry>
      <material name="Gray">
        <color rgba="0.5 0.5 0.5 1.0"/>
      </material>
    </visual>
    <collision>
      <origin rpy="1.5707963267948966 0 0" xyz="0 0 0"/>
      <geometry>
        <cylinder length="0.04" radius="0.1"/>
      </geometry>
    </collision>
    <inertial>
      <origin rpy="1.5707963267948966 0 0" xyz="0 0 0"/>
      <mass value="0.5"/>
      <inertia ixx="0.0013166666666666667" ixy="0" ixz="0" iyy="0.0013166666666666667" iyz="0" izz="0.0025000000000000005"/>
    </inertial>
  </link>
  <joint name="drivewhl_l_joint" type="continuous">
    <parent link="base_link"/>
    <child link="drivewhl_l_link"/>
    <origin rpy="0 0 0" xyz="-0.12 0.125 -0.05"/>
    <axis xyz="0 1 0"/>
  </joint>
  <link name="drivewhl_r_link">
    <visual>
      <origin rpy="1.5707963267948966 0 0" xyz="0 0 0"/>
      <geometry>
        <cylinder length="0.04" radius="0.1"/>
      </geometry>
      <material name="Gray">
        <color rgba="0.5 0.5 0.5 1.0"/>
      </material>
    </visual>
    <collision>
      <origin rpy="1.5707963267948966 0 0" xyz="0 0 0"/>
      <geometry>
        <cylinder length="0.04" radius="0.1"/>
      </geometry>
    </collision>
    <inertial>
      <origin rpy="1.5707963267948966 0 0" xyz="0 0 0"/>
      <mass value="0.5"/>
      <inertia ixx="0.0013166666666666667" ixy="0" ixz="0" iyy="0.0013166666666666667" iyz="0" izz="0.0025000000000000005"/>
    </inertial>
  </link>
  <joint name="drivewhl_r_joint" type="continuous">
    <parent link="base_link"/>
    <child link="drivewhl_r_link"/>
    <origin rpy="0 0 0" xyz="-0.12 -0.125 -0.05"/>
    <axis xyz="0 1 0"/>
  </joint>
  <link name="drivewhl_b_link">
    <visual>
      <origin rpy="1.5707963267948966 0 0" xyz="0 0 0"/>
      <geometry>
        <cylinder length="0.04" radius="0.1"/>
      </geometry>
      <material name="Gray">
        <color rgba="0.5 0.5 0.5 1.0"/>
      </material>
    </visual>
    <collision>
      <origin rpy="1.5707963267948966 0 0" xyz="0 0 0"/>
      <geometry>
        <cylinder length="0.04" radius="0.1"/>
      </geometry>
    </collision>
    <inertial>
      <origin rpy="1.5707963267948966 0 0" xyz="0 0 0"/>
      <mass value="0.5"/>
      <inertia ixx="0.0013166666666666667" ixy="0" ixz="0" iyy="0.0013166666666666667" iyz="0" izz="0.0025000000000000005"/>
    </inertial>
  </link>
  <joint name="drivewhl_b_joint" type="continuous">
    <parent link="base_link"/>
    <child link="drivewhl_b_link"/>
    <origin rpy="0 0 0" xyz="0.12 0.125 -0.05"/>
    <axis xyz="0 1 0"/>
  </joint>
  <link name="drivewhl_f_link">
    <visual>
      <origin rpy="1.5707963267948966 0 0" xyz="0 0 0"/>
      <geometry>
        <cylinder length="0.04" radius="0.1"/>
      </geometry>
      <material name="Gray">
        <color rgba="0.5 0.5 0.5 1.0"/>
      </material>
    </visual>
    <collision>
      <origin rpy="1.5707963267948966 0 0" xyz="0 0 0"/>
      <geometry>
        <cylinder length="0.04" radius="0.1"/>
      </geometry>
    </collision>
    <inertial>
      <origin rpy="1.5707963267948966 0 0" xyz="0 0 0"/>
      <mass value="0.5"/>
      <inertia ixx="0.0013166666666666667" ixy="0" ixz="0" iyy="0.0013166666666666667" iyz="0" izz="0.0025000000000000005"/>
    </inertial>
  </link>
  <joint name="drivewhl_f_joint" type="continuous">
    <parent link="base_link"/>
    <child link="drivewhl_f_link"/>
    <origin rpy="0 0 0" xyz="0.12 -0.125 -0.05"/>
    <axis xyz="0 1 0"/>
  </joint>
</robot>
